<mujoco model="robot_with_weave_poles">
    <compiler angle="radian" coordinate="local"/>
    <option gravity="0 0 -9.81" timestep="0.001"/>

    <asset>
        <!-- Robot assets -->
        <mesh name="controller_torso" file="./controller_torso.stl" scale="0.001 0.001 0.001"/>
        <mesh name="motor_torso" file="./motor_torso.stl" scale="0.001 0.001 0.001"/>
        <mesh name="legs" file="./legs.stl" scale="0.001 0.001 0.001"/>
        
        <!-- Weave Pole assets -->
        <mesh name="weave_pole" file="../models/google_barkour_v0/assets/cone1__1default.stl"/>

        <!-- Ground material -->
        <texture name="grid" type="2d" builtin="checker" width="512" height="512" rgb1="0.9 0.9 0.9" rgb2="0.7 0.7 0.7"/>
        <material name="grid" texture="grid" texrepeat="5 5" reflectance="0.2"/>
    </asset>

    <worldbody>
        <!-- Ground Plane -->
        <geom name="floor" type="plane" pos="0 0 0" size="0 0 0.25" material="grid"/>

        <!-- Robot -->
        <body name="controller_torso_body" pos="0 0 0.05" euler="-1.57 3.14 0">
            <joint name="FLOATING" type="free"/>
            <geom type="mesh" mesh="controller_torso" rgba="1.0 0.502 0.545 1"/>
             <!-- Adding a camera -->
            <camera euler="0.8 0 3.14152" fovy="60" name="main_camera" pos="0.05 -0.05 0" />
            <!-- Motor torso -->
            <body name="motor_torso_body" pos="0 0 0.11">
                <joint name="z_rotation_joint" type="hinge" axis="0 0 1" pos="0.025 0.02 0" range="-1.57 1.57" damping="0.05"/>
                <geom type="mesh" mesh="motor_torso" rgba="1.0 0.502 0.545 1"/>
                
                <!-- Back Leg -->
                <body name="back_leg" pos="-0.065 0.0497 0.08" euler="3.14 0 0">
                    <joint axis="0 1 0" damping="0.05" name="LEG2" pos="0.088 0.02 0.015" range="-1.5707963 1.5707963" type="hinge"/>
                    <geom type="mesh" mesh="legs" rgba="0.471 0.824 0.243 1"/>
                </body>
            </body>

            <!-- Front Leg -->
            <body name="front_leg" pos="-0.065 0.0497 0.05" euler="3.14 0 0">
                <joint axis="0 1 0" damping="0.05" name="LEG1" pos="0.088 0.02 0.015" range="-1.5707963 1.5707963" type="hinge"/>
                <geom type="mesh" mesh="legs" rgba="0.471 0.824 0.243 1"/>
            </body>
        </body>

        <!-- Weave Poles -->

        <geom pos="1.0 -0.5 0.02" quat="0 0 -1 0" type="mesh" mesh="weave_pole" rgba="0.945 0.597 0 1"/>
        <geom pos="1.5 -0.8 0.02" quat="0 0 -1 0" type="mesh" mesh="weave_pole" rgba="0.203 0.656 0.324 1"/>
        <geom pos="2.0 -0.4 0.02" quat="0 0 -1 0" type="mesh" mesh="weave_pole" rgba="0.824 0.412 0.118 1"/>
        <geom pos="2.5 -0.7 0.02" quat="0 0 -1 0" type="mesh" mesh="weave_pole" rgba="0.341 0.545 0.341 1"/>
        <geom pos="3.0 -0.5 0.02" quat="0 0 -1 0" type="mesh" mesh="weave_pole" rgba="0.6 0.2 0.8 1"/>
        <geom pos="3.5 -0.9 0.02" quat="0 0 -1 0" type="mesh" mesh="weave_pole" rgba="0.2 0.7 0.3 1"/>
        <geom pos="4.0 -0.6 0.02" quat="0 0 -1 0" type="mesh" mesh="weave_pole" rgba="0.945 0.597 0 1"/>
        <geom pos="4.5 -0.8 0.02" quat="0 0 -1 0" type="mesh" mesh="weave_pole" rgba="0.203 0.656 0.324 1"/>

        <geom pos="0.5 -1.0 0.02" quat="0 0 -1 0" type="mesh" mesh="weave_pole" rgba="0.824 0.314 0.157 1"/>
        <geom pos="1.0 -1.2 0.02" quat="0 0 -1 0" type="mesh" mesh="weave_pole" rgba="0.231 0.545 0.231 1"/>
        <geom pos="1.5 -1.0 0.02" quat="0 0 -1 0" type="mesh" mesh="weave_pole" rgba="0.824 0.314 0.157 1"/>
        <geom pos="2.0 -1.3 0.02" quat="0 0 -1 0" type="mesh" mesh="weave_pole" rgba="0.231 0.545 0.231 1"/>
        <geom pos="2.5 -1.1 0.02" quat="0 0 -1 0" type="mesh" mesh="weave_pole" rgba="0.824 0.314 0.157 1"/>
        <geom pos="3.0 -1.4 0.02" quat="0 0 -1 0" type="mesh" mesh="weave_pole" rgba="0.231 0.545 0.231 1"/>
        <geom pos="3.5 -1.2 0.02" quat="0 0 -1 0" type="mesh" mesh="weave_pole" rgba="0.824 0.314 0.157 1"/>
        <geom pos="4.0 -1.5 0.02" quat="0 0 -1 0" type="mesh" mesh="weave_pole" rgba="0.231 0.545 0.231 1"/>
        <geom pos="4.5 -1.3 0.02" quat="0 0 -1 0" type="mesh" mesh="weave_pole" rgba="0.824 0.314 0.157 1"/>

        <geom pos="0.5 -1.8 0.02" quat="0 0 -1 0" type="mesh" mesh="weave_pole" rgba="0.6 0.2 0.8 1"/>
        <geom pos="1.0 -2.0 0.02" quat="0 0 -1 0" type="mesh" mesh="weave_pole" rgba="0.2 0.7 0.3 1"/>
        <geom pos="1.5 -1.7 0.02" quat="0 0 -1 0" type="mesh" mesh="weave_pole" rgba="0.6 0.2 0.8 1"/>
        <geom pos="2.0 -1.9 0.02" quat="0 0 -1 0" type="mesh" mesh="weave_pole" rgba="0.2 0.7 0.3 1"/>
        <geom pos="2.5 -1.6 0.02" quat="0 0 -1 0" type="mesh" mesh="weave_pole" rgba="0.6 0.2 0.8 1"/>
        <geom pos="3.0 -1.8 0.02" quat="0 0 -1 0" type="mesh" mesh="weave_pole" rgba="0.2 0.7 0.3 1"/>
        <geom pos="3.5 -1.5 0.02" quat="0 0 -1 0" type="mesh" mesh="weave_pole" rgba="0.6 0.2 0.8 1"/>
        <geom pos="4.0 -1.7 0.02" quat="0 0 -1 0" type="mesh" mesh="weave_pole" rgba="0.2 0.7 0.3 1"/>
        <geom pos="4.5 -1.4 0.02" quat="0 0 -1 0" type="mesh" mesh="weave_pole" rgba="0.6 0.2 0.8 1"/>

        <geom pos="0.5 -2.6 0.02" quat="0 0 -1 0" type="mesh" mesh="weave_pole" rgba="0.945 0.597 0 1"/>
        <geom pos="1.0 -2.9 0.02" quat="0 0 -1 0" type="mesh" mesh="weave_pole" rgba="0.203 0.656 0.324 1"/>
        <geom pos="1.5 -2.5 0.02" quat="0 0 -1 0" type="mesh" mesh="weave_pole" rgba="0.824 0.412 0.118 1"/>
        <geom pos="2.0 -2.8 0.02" quat="0 0 -1 0" type="mesh" mesh="weave_pole" rgba="0.341 0.545 0.341 1"/>
        <geom pos="2.5 -2.4 0.02" quat="0 0 -1 0" type="mesh" mesh="weave_pole" rgba="0.6 0.2 0.8 1"/>
        <geom pos="3.0 -2.9 0.02" quat="0 0 -1 0" type="mesh" mesh="weave_pole" rgba="0.2 0.7 0.3 1"/>
        <geom pos="3.5 -2.7 0.02" quat="0 0 -1 0" type="mesh" mesh="weave_pole" rgba="0.945 0.597 0 1"/>
        <geom pos="4.0 -2.5 0.02" quat="0 0 -1 0" type="mesh" mesh="weave_pole" rgba="0.203 0.656 0.324 1"/>
        <geom pos="4.5 -2.8 0.02" quat="0 0 -1 0" type="mesh" mesh="weave_pole" rgba="0.824 0.412 0.118 1"/>


        <!-- Light -->
        <light name="main_light" pos="0 0 5" dir="0 0 -1" diffuse="1 1 1" specular="0.3 0.3 0.3" directional="true"/>
    </worldbody>

    <!-- Actuators -->
    <actuator>
        <motor joint="z_rotation_joint" name="z_rotation_joint_act"/>
        <motor joint="LEG1" name="LEG1_act"/>
        <motor joint="LEG2" name="LEG2_act"/>
    </actuator>
</mujoco>