<mujoco model='ec518_PATriQ'>
    <compiler angle='radian' coordinate='local'/>
    <option gravity='0 0 9.81' timestep='0.01'/> 
    <default>
    <geom conaffinity="0" contype="4"/>
    <!-- condim='1' solref='0.005 1' solimp ="0.9 0.95 0.001 0.5 2"/>-->
  </default>
  
    <asset>
        <mesh name='controller_torso' file='./controller_torso.stl' scale='0.001 0.001 0.001'/>
        <mesh name='motor_torso' file='./motor_torso.stl' scale='0.001 0.001 0.001'/>
        <mesh name='legs' file='./legs.stl' scale='0.001 0.001 0.001'/>
    </asset>
    <worldbody>
        <!-- Ground plane with grid pattern -->
        <geom type='plane' pos='0 0 0' size='5 5 0.1' rgba='0.9 0.9 0.9 1' material='grid'/>
        <!-- Controller Torso -->
        <body name='controller_torso_body' pos='0 0 0.05' euler='-1.57 3.14 0'>
            <geom type='mesh' mesh='controller_torso' rgba='1.0 0.502 0.545 1'/>
            <!-- Motor torso -->
            <body name='motor_torso_body' pos='0 0 0.11'>
                <geom type='mesh' mesh='motor_torso' rgba='1.0 0.502 0.545 1'/>
            </body>
            <!-- Front Leg (Green) -->
            <body name='front_leg' pos='-0.065 0.0497 0.05' euler='3.14 0 0'>
                <joint axis='0 1 0' damping='0.01' name='LEG1' pos='0.09 0.02 0.018' range='-0.1 0.1' type='hinge'/>
                <geom type='mesh' mesh='legs' rgba='0.471 0.824 0.243 1'/>
            </body>
            <!-- Back Leg (Purple) -->
            <body name='back_leg' pos='-0.065 0.0497 0.197' euler='3.14 0 0'>
                <geom type='mesh' mesh='legs' rgba='0.471 0.824 0.243 1'/>
            </body>
        </body>
        <!-- Light source defined in worldbody -->
        <light name='main_light' pos='0 0 5' dir='0 0 -1' diffuse='1 1 1' specular='0.3 0.3 0.3' directional='true'/>
    </worldbody>
    <asset>
        <!-- Grid material for the ground -->
        <texture name='grid' type='2d' builtin='checker' width='512' height='512' rgb1='0.9 0.9 0.9' rgb2='0.7 0.7 0.7'/>
        <material name='grid' texture='grid' texrepeat='5 5' reflectance='0.2'/>
    </asset>
</mujoco>









